Workbook

Sheet Planilla de Riesgos
A1: ID | B1: Categoría | C1: Riesgo | D1: Causa probable | E1: Consecuencia si ocurre | F1: Prob. (1-5) | G1: Impacto (1-5) | H1: Nivel | I1: Severidad | J1: Estrategia | K1: Acciones de mitigación (preventivas) | L1: Plan de contingencia (si ocurre) | M1: Responsable | N1: Sprint / Fase | O1: Prob. residual | P1: Impacto residual | Q1: Nivel residual | R1: Severidad residual | S1: Estado
A2: R-01 | B2: Alcance | C2: Cambios de requerimientos por parte de la agencia durante el desarrollo | D2: La agencia no tiene sus procesos formalizados y ajusta lo solicitado a medida que ve los avances | E2: Retrabajo, sprints desbordados y riesgo de no alcanzar a cerrar las tres fases comprometidas | F2: 4 | G2: 4 | H2: =F2*G2 | I2: =IF(H2="","",IF(H2<=5,"Bajo",IF(H2<=10,"Medio",IF(H2<=15,"Alto","Crítico")))) | J2: Mitigar | K2: Backlog congelado al iniciar cada sprint; toda solicitud nueva ingresa al Product Backlog y se prioriza en la siguiente planificación; acta de acuerdos firmada en cada reunión de validación | L2: Reducir la Fase 3 a un MVP del portal (calendario editorial y aprobación de contenido) y documentar formalmente lo postergado | M2: Felipe Gutiérrez | N2: Sprint 0 - Sprint 5 | O2: 2 | P2: 4 | Q2: =O2*P2 | R2: =IF(Q2="","",IF(Q2<=5,"Bajo",IF(Q2<=10,"Medio",IF(Q2<=15,"Alto","Crítico")))) | S2: Activo
A3: R-02 | B3: Alcance | C3: Solicitudes informales de funcionalidades por canales no oficiales | D3: La agencia pide cambios por WhatsApp o conversaciones sueltas que no quedan registradas | E3: Se desarrollan funciones no acordadas y se pierde trazabilidad de lo comprometido | F3: 4 | G3: 3 | H3: =F3*G3 | I3: =IF(H3="","",IF(H3<=5,"Bajo",IF(H3<=10,"Medio",IF(H3<=15,"Alto","Crítico")))) | J3: Mitigar | K3: Canal único de solicitudes definido en el Sprint 0; todo pedido informal se traslada al Product Backlog antes de ser trabajado; confirmación escrita de cada acuerdo | L3: Revisar el backlog junto a la agencia y descartar formalmente lo que no corresponda al alcance del Capstone | M3: Esteban Morales | N3: Sprint 0 - Sprint 5 | O3: 2 | P3: 2 | Q3: =O3*P3 | R3: =IF(Q3="","",IF(Q3<=5,"Bajo",IF(Q3<=10,"Medio",IF(Q3<=15,"Alto","Crítico")))) | S3: Activo
A4: R-03 | B4: Alcance | C4: Expectativa de que la plataforma reemplace herramientas fuera del alcance | D4: La agencia asume que el sistema incluirá facturación, contabilidad o gestión de pagos | E4: Insatisfacción al momento de la entrega pese a cumplir lo comprometido | F4: 3 | G4: 3 | H4: =F4*G4 | I4: =IF(H4="","",IF(H4<=5,"Bajo",IF(H4<=10,"Medio",IF(H4<=15,"Alto","Crítico")))) | J4: Evitar | K4: Documento de alcance con un apartado explícito de exclusiones, revisado y aceptado por la agencia; recordatorio de las exclusiones en cada revisión de avance | L4: Dejar documentada la integración futura como una recomendación en el informe final, sin desarrollarla | M4: Felipe Gutiérrez | N4: Sprint 0 | O4: 1 | P4: 3 | Q4: =O4*P4 | R4: =IF(Q4="","",IF(Q4<=5,"Bajo",IF(Q4<=10,"Medio",IF(Q4<=15,"Alto","Crítico")))) | S4: Activo
A5: R-04 | B5: Alcance | C5: Límite difuso entre lo que resuelve la plataforma y lo que sigue en herramientas externas | D5: Procesos de la agencia que quedan a medio camino entre el sistema y sus herramientas actuales | E5: Duplicidad de información y procesos que nadie ejecuta completamente en ningún lado | F5: 3 | G5: 3 | H5: =F5*G5 | I5: =IF(H5="","",IF(H5<=5,"Bajo",IF(H5<=10,"Medio",IF(H5<=15,"Alto","Crítico")))) | J5: Mitigar | K5: Mapa de procesos levantado en el Sprint 0 indicando, para cada actividad, si queda dentro o fuera del sistema; validación de ese mapa con los dos socios | L5: Documentar los puntos de traspaso manual en el manual de administración para que la agencia los opere de forma consciente | M5: Esteban Morales | N5: Sprint 0 - Sprint 1 | O5: 2 | P5: 2 | Q5: =O5*P5 | R5: =IF(Q5="","",IF(Q5<=5,"Bajo",IF(Q5<=10,"Medio",IF(Q5<=15,"Alto","Crítico")))) | S5: Activo
A6: R-05 | B6: Stakeholders | C6: Baja disponibilidad de los socios de la agencia para validar avances | D6: La agencia la operan solo dos personas, absorbidas por el día a día con sus clientes | E6: Validaciones tardías y decisiones tomadas sobre supuestos no confirmados | F6: 4 | G6: 3 | H6: =F6*G6 | I6: =IF(H6="","",IF(H6<=5,"Bajo",IF(H6<=10,"Medio",IF(H6<=15,"Alto","Crítico")))) | J6: Mitigar | K6: Agenda fija de revisión quincenal de 30 minutos acordada en el Sprint 0; material enviado con 48 horas de anticipación; canal de validación asincrónica por correo cuando no haya reunión | L6: Avanzar con supuestos explícitamente documentados y marcados como pendientes de validación para la siguiente revisión | M6: Esteban Morales | N6: Sprint 0 - Sprint 5 | O6: 2 | P6: 3 | Q6: =O6*P6 | R6: =IF(Q6="","",IF(Q6<=5,"Bajo",IF(Q6<=10,"Medio",IF(Q6<=15,"Alto","Crítico")))) | S6: Activo
A7: R-06 | B7: Stakeholders | C7: Definiciones contradictorias entre los dos socios de la agencia | D7: Cada socio tiene una visión distinta de cómo debe operar el proceso comercial | E7: Desarrollo detenido a la espera de una definición o funcionalidad rehecha tras la contradicción | F7: 3 | G7: 3 | H7: =F7*G7 | I7: =IF(H7="","",IF(H7<=5,"Bajo",IF(H7<=10,"Medio",IF(H7<=15,"Alto","Crítico")))) | J7: Mitigar | K7: Designar a un único interlocutor con autoridad de decisión; registrar cada definición en acta; presentar las alternativas en conjunto cuando exista discrepancia | L7: Escalar la decisión pendiente al docente guía y avanzar con la alternativa más simple, documentando el supuesto | M7: Felipe Gutiérrez | N7: Sprint 0 - Sprint 3 | O7: 2 | P7: 2 | Q7: =O7*P7 | R7: =IF(Q7="","",IF(Q7<=5,"Bajo",IF(Q7<=10,"Medio",IF(Q7<=15,"Alto","Crítico")))) | S7: Activo
A8: R-07 | B8: Stakeholders | C8: La agencia no entrega información real para poblar y probar el sistema | D8: Datos de clientes, planes y precios dispersos o considerados sensibles por la agencia | E8: Pruebas realizadas con datos ficticios que no reflejan el comportamiento real del sistema | F8: 3 | G8: 3 | H8: =F8*G8 | I8: =IF(H8="","",IF(H8<=5,"Bajo",IF(H8<=10,"Medio",IF(H8<=15,"Alto","Crítico")))) | J8: Mitigar | K8: Solicitar un conjunto acotado de datos reales anonimizados en el Sprint 1; acuerdo de confidencialidad simple firmado por el equipo | L8: Construir un set de datos sintéticos que replique volúmenes y casos límite realistas | M8: Christian Cuadra | N8: Sprint 1 - Sprint 2 | O8: 2 | P8: 2 | Q8: =O8*P8 | R8: =IF(Q8="","",IF(Q8<=5,"Bajo",IF(Q8<=10,"Medio",IF(Q8<=15,"Alto","Crítico")))) | S8: Activo
A9: R-08 | B9: Stakeholders | C9: Los clientes finales de la agencia no adoptan el portal | D9: Están acostumbrados a coordinar todo por WhatsApp y correo con la agencia | E9: El portal queda sin uso real y no se puede evidenciar su valor en la entrega final | F9: 3 | G9: 4 | H9: =F9*G9 | I9: =IF(H9="","",IF(H9<=5,"Bajo",IF(H9<=10,"Medio",IF(H9<=15,"Alto","Crítico")))) | J9: Mitigar | K9: Diseño enfocado en simplicidad y acceso desde móvil; notificaciones por correo que llevan directo a la acción dentro del portal; plan de puesta en marcha con dos clientes piloto | L9: Documentar la adopción como un indicador de la marcha blanca y evidenciar el funcionamiento con los clientes piloto | M9: Esteban Morales | N9: Sprint 3 - Sprint 5 | O9: 2 | P9: 3 | Q9: =O9*P9 | R9: =IF(Q9="","",IF(Q9<=5,"Bajo",IF(Q9<=10,"Medio",IF(Q9<=15,"Alto","Crítico")))) | S9: Activo
A10: R-09 | B10: Equipo | C10: Sobrecarga académica del equipo en períodos de evaluaciones | D10: Los tres integrantes cursan otras asignaturas en paralelo al Capstone | E10: Caída de la velocidad del equipo y atraso en los hitos comprometidos | F10: 4 | G10: 3 | H10: =F10*G10 | I10: =IF(H10="","",IF(H10<=5,"Bajo",IF(H10<=10,"Medio",IF(H10<=15,"Alto","Crítico")))) | J10: Mitigar | K10: Carta Gantt construida considerando las semanas de evaluación de la carrera; holgura de un 20% en la planificación de cada sprint; tablero Scrum con la carga de cada integrante visible | L10: Redistribuir las historias entre los integrantes y desplazar al sprint siguiente las funcionalidades no críticas | M10: Christian Cuadra | N10: Sprint 1 - Sprint 5 | O10: 3 | P10: 2 | Q10: =O10*P10 | R10: =IF(Q10="","",IF(Q10<=5,"Bajo",IF(Q10<=10,"Medio",IF(Q10<=15,"Alto","Crítico")))) | S10: Activo
A11: R-10 | B11: Equipo | C11: Ausencia prolongada o deserción de un integrante del equipo | D11: Enfermedad, situación personal o retiro de la carrera durante el semestre | E11: Pérdida del conocimiento del módulo a cargo y redistribución de carga sobre los demás | F11: 2 | G11: 5 | H11: =F11*G11 | I11: =IF(H11="","",IF(H11<=5,"Bajo",IF(H11<=10,"Medio",IF(H11<=15,"Alto","Crítico")))) | J11: Mitigar | K11: Trabajo transversal sin especialización fija; todo el código y la documentación en repositorio compartido; revisión cruzada de cada entregable por al menos otro integrante | L11: Reasignar los módulos pendientes y solicitar formalmente al docente guía un ajuste del alcance comprometido | M11: Felipe Gutiérrez | N11: Sprint 0 - Sprint 5 | O11: 2 | P11: 3 | Q11: =O11*P11 | R11: =IF(Q11="","",IF(Q11<=5,"Bajo",IF(Q11<=10,"Medio",IF(Q11<=15,"Alto","Crítico")))) | S11: Activo
A12: R-11 | B12: Equipo | C12: Diferencias de nivel técnico entre los integrantes | D12: Experiencia previa dispar en desarrollo web, bases de datos y servicios en la nube | E12: Cuellos de botella en las tareas que solo un integrante puede resolver | F12: 3 | G12: 3 | H12: =F12*G12 | I12: =IF(H12="","",IF(H12<=5,"Bajo",IF(H12<=10,"Medio",IF(H12<=15,"Alto","Crítico")))) | J12: Mitigar | K12: Programación en pareja en los módulos críticos; sesiones internas de traspaso al cierre de cada sprint; documentación técnica de cada decisión en el repositorio | L12: Redistribuir la tarea bloqueada al integrante con mayor dominio y dejarla documentada como material de estudio interno | M12: Christian Cuadra | N12: Sprint 0 - Sprint 5 | O12: 2 | P12: 2 | Q12: =O12*P12 | R12: =IF(Q12="","",IF(Q12<=5,"Bajo",IF(Q12<=10,"Medio",IF(Q12<=15,"Alto","Crítico")))) | S12: Activo
A13: R-12 | B13: Equipo | C13: Trabajo duplicado o incompatible por coordinación deficiente | D13: Falta de una rutina de sincronización y de asignación clara de tareas en el tablero | E13: Horas perdidas y conflictos al integrar el código de distintos integrantes | F13: 3 | G13: 3 | H13: =F13*G13 | I13: =IF(H13="","",IF(H13<=5,"Bajo",IF(H13<=10,"Medio",IF(H13<=15,"Alto","Crítico")))) | J13: Mitigar | K13: Daily breve tres veces por semana; tablero Scrum como única fuente de asignación; ramas por funcionalidad con integración frecuente al tronco principal | L13: Resolver el conflicto en una sesión conjunta de integración y definir un responsable único del módulo afectado | M13: Esteban Morales | N13: Sprint 1 - Sprint 5 | O13: 2 | P13: 2 | Q13: =O13*P13 | R13: =IF(Q13="","",IF(Q13<=5,"Bajo",IF(Q13<=10,"Medio",IF(Q13<=15,"Alto","Crítico")))) | S13: Activo
... A70: R-69 | B70: Entregables académicos | C70: Falla técnica del equipamiento durante la defensa final | D70: Dependencia de conexión a internet, proyector y equipo personal el día de la presentación | E70: Pérdida de tiempo de exposición o imposibilidad de mostrar el sistema | F70: 3 | G70: 4 | H70: =F70*G70 | I70: =IF(H70="","",IF(H70<=5,"Bajo",IF(H70<=10,"Medio",IF(H70<=15,"Alto","Crítico")))) | J70: Mitigar | K70: Presentación y video de demostración descargados localmente en dos equipos distintos; conexión móvil como respaldo; prueba del equipamiento antes de la hora de inicio | L70: Exponer desde el equipo de respaldo con el material descargado localmente | M70: Esteban Morales | N70: Sprint 5 | O70: 1 | P70: 3 | Q70: =O70*P70 | R70: =IF(Q70="","",IF(Q70<=5,"Bajo",IF(Q70<=10,"Medio",IF(Q70<=15,"Alto","Crítico")))) | S70: Activo
A72: Nota: Nivel = Probabilidad × Impacto (columnas H y Q, calculadas automáticamente). El nivel residual corresponde a la exposición esperada una vez aplicadas las acciones de mitigación. Probabilidad, impacto y responsables fueron estimados por el equipo del proyecto; los criterios de cada valor están en la hoja «Escalas y Criterios».

Sheet Matriz y Resumen
A1: Matriz de riesgo 5x5 — cantidad de riesgos por combinación (exposición inherente)
A3: Probabilidad \ Impacto | B3: 1 - Insignificante | C3: 2 - Menor | D3: 3 - Moderado | E3: 4 - Mayor | F3: 5 - Crítico
A4: 5 - Casi seguro | B4: =COUNTIFS('Planilla de Riesgos'!$F$2:$F$70,5,'Planilla de Riesgos'!$G$2:$G$70,1) | C4: =COUNTIFS('Planilla de Riesgos'!$F$2:$F$70,5,'Planilla de Riesgos'!$G$2:$G$70,2) | D4: =COUNTIFS('Planilla de Riesgos'!$F$2:$F$70,5,'Planilla de Riesgos'!$G$2:$G$70,3) | E4: =COUNTIFS('Planilla de Riesgos'!$F$2:$F$70,5,'Planilla de Riesgos'!$G$2:$G$70,4) | F4: =COUNTIFS('Planilla de Riesgos'!$F$2:$F$70,5,'Planilla de Riesgos'!$G$2:$G$70,5)
A5: 4 - Probable | B5: =COUNTIFS('Planilla de Riesgos'!$F$2:$F$70,4,'Planilla de Riesgos'!$G$2:$G$70,1) | C5: =COUNTIFS('Planilla de Riesgos'!$F$2:$F$70,4,'Planilla de Riesgos'!$G$2:$G$70,2) | D5: =COUNTIFS('Planilla de Riesgos'!$F$2:$F$70,4,'Planilla de Riesgos'!$G$2:$G$70,3) | E5: =COUNTIFS('Planilla de Riesgos'!$F$2:$F$70,4,'Planilla de Riesgos'!$G$2:$G$70,4) | F5: =COUNTIFS('Planilla de Riesgos'!$F$2:$F$70,4,'Planilla de Riesgos'!$G$2:$G$70,5)
A6: 3 - Posible | B6: =COUNTIFS('Planilla de Riesgos'!$F$2:$F$70,3,'Planilla de Riesgos'!$G$2:$G$70,1) | C6: =COUNTIFS('Planilla de Riesgos'!$F$2:$F$70,3,'Planilla de Riesgos'!$G$2:$G$70,2) | D6: =COUNTIFS('Planilla de Riesgos'!$F$2:$F$70,3,'Planilla de Riesgos'!$G$2:$G$70,3) | E6: =COUNTIFS('Planilla de Riesgos'!$F$2:$F$70,3,'Planilla de Riesgos'!$G$2:$G$70,4) | F6: =COUNTIFS('Planilla de Riesgos'!$F$2:$F$70,3,'Planilla de Riesgos'!$G$2:$G$70,5)
A7: 2 - Poco probable | B7: =COUNTIFS('Planilla de Riesgos'!$F$2:$F$70,2,'Planilla de Riesgos'!$G$2:$G$70,1) | C7: =COUNTIFS('Planilla de Riesgos'!$F$2:$F$70,2,'Planilla de Riesgos'!$G$2:$G$70,2) | D7: =COUNTIFS('Planilla de Riesgos'!$F$2:$F$70,2,'Planilla de Riesgos'!$G$2:$G$70,3) | E7: =COUNTIFS('Planilla de Riesgos'!$F$2:$F$70,2,'Planilla de Riesgos'!$G$2:$G$70,4) | F7: =COUNTIFS('Planilla de Riesgos'!$F$2:$F$70,2,'Planilla de Riesgos'!$G$2:$G$70,5)
A8: 1 - Raro | B8: =COUNTIFS('Planilla de Riesgos'!$F$2:$F$70,1,'Planilla de Riesgos'!$G$2:$G$70,1) | C8: =COUNTIFS('Planilla de Riesgos'!$F$2:$F$70,1,'Planilla de Riesgos'!$G$2:$G$70,2) | D8: =COUNTIFS('Planilla de Riesgos'!$F$2:$F$70,1,'Planilla de Riesgos'!$G$2:$G$70,3) | E8: =COUNTIFS('Planilla de Riesgos'!$F$2:$F$70,1,'Planilla de Riesgos'!$G$2:$G$70,4) | F8: =COUNTIFS('Planilla de Riesgos'!$F$2:$F$70,1,'Planilla de Riesgos'!$G$2:$G$70,5)
A11: Resumen por nivel de severidad
A12: Severidad | B12: Rango (P×I) | C12: Riesgos inherentes | D12: Riesgos residuales
A13: Bajo | B13: 1 a 5 | C13: =COUNTIFS('Planilla de Riesgos'!$H$2:$H$70,">="&1,'Planilla de Riesgos'!$H$2:$H$70,"<="&5) | D13: =COUNTIFS('Planilla de Riesgos'!$Q$2:$Q$70,">="&1,'Planilla de Riesgos'!$Q$2:$Q$70,"<="&5)
A14: Medio | B14: 6 a 10 | C14: =COUNTIFS('Planilla de Riesgos'!$H$2:$H$70,">="&6,'Planilla de Riesgos'!$H$2:$H$70,"<="&10) | D14: =COUNTIFS('Planilla de Riesgos'!$Q$2:$Q$70,">="&6,'Planilla de Riesgos'!$Q$2:$Q$70,"<="&10)
A15: Alto | B15: 11 a 15 | C15: =COUNTIFS('Planilla de Riesgos'!$H$2:$H$70,">="&11,'Planilla de Riesgos'!$H$2:$H$70,"<="&15) | D15: =COUNTIFS('Planilla de Riesgos'!$Q$2:$Q$70,">="&11,'Planilla de Riesgos'!$Q$2:$Q$70,"<="&15)
A16: Crítico | B16: 16 a 25 | C16: =COUNTIFS('Planilla de Riesgos'!$H$2:$H$70,">="&16,'Planilla de Riesgos'!$H$2:$H$70,"<="&25) | D16: =COUNTIFS('Planilla de Riesgos'!$Q$2:$Q$70,">="&16,'Planilla de Riesgos'!$Q$2:$Q$70,"<="&25)
A17: Total | C17: =SUM(C13:C16) | D17: =SUM(D13:D16)
A20: Resumen por categoría
A21: Categoría | B21: N° de riesgos | C21: Nivel promedio | D21: Nivel máximo | E21: Riesgos altos o críticos
A22: Alcance | B22: =COUNTIF('Planilla de Riesgos'!$B$2:$B$70,$A22) | C22: =IFERROR(ROUND(AVERAGEIF('Planilla de Riesgos'!$B$2:$B$70,$A22,'Planilla de Riesgos'!$H$2:$H$70),1),0) | D22: =SUMPRODUCT(MAX(('Planilla de Riesgos'!$B$2:$B$70=$A22)*'Planilla de Riesgos'!$H$2:$H$70)) | E22: =COUNTIFS('Planilla de Riesgos'!$B$2:$B$70,$A22,'Planilla de Riesgos'!$H$2:$H$70,">=11")
A23: Stakeholders | B23: =COUNTIF('Planilla de Riesgos'!$B$2:$B$70,$A23) | C23: =IFERROR(ROUND(AVERAGEIF('Planilla de Riesgos'!$B$2:$B$70,$A23,'Planilla de Riesgos'!$H$2:$H$70),1),0) | D23: =SUMPRODUCT(MAX(('Planilla de Riesgos'!$B$2:$B$70=$A23)*'Planilla de Riesgos'!$H$2:$H$70)) | E23: =COUNTIFS('Planilla de Riesgos'!$B$2:$B$70,$A23,'Planilla de Riesgos'!$H$2:$H$70,">=11")
A24: Equipo | B24: =COUNTIF('Planilla de Riesgos'!$B$2:$B$70,$A24) | C24: =IFERROR(ROUND(AVERAGEIF('Planilla de Riesgos'!$B$2:$B$70,$A24,'Planilla de Riesgos'!$H$2:$H$70),1),0) | D24: =SUMPRODUCT(MAX(('Planilla de Riesgos'!$B$2:$B$70=$A24)*'Planilla de Riesgos'!$H$2:$H$70)) | E24: =COUNTIFS('Planilla de Riesgos'!$B$2:$B$70,$A24,'Planilla de Riesgos'!$H$2:$H$70,">=11")
A25: Planificación | B25: =COUNTIF('Planilla de Riesgos'!$B$2:$B$70,$A25) | C25: =IFERROR(ROUND(AVERAGEIF('Planilla de Riesgos'!$B$2:$B$70,$A25,'Planilla de Riesgos'!$H$2:$H$70),1),0) | D25: =SUMPRODUCT(MAX(('Planilla de Riesgos'!$B$2:$B$70=$A25)*'Planilla de Riesgos'!$H$2:$H$70)) | E25: =COUNTIFS('Planilla de Riesgos'!$B$2:$B$70,$A25,'Planilla de Riesgos'!$H$2:$H$70,">=11")
A26: Técnico | B26: =COUNTIF('Planilla de Riesgos'!$B$2:$B$70,$A26) | C26: =IFERROR(ROUND(AVERAGEIF('Planilla de Riesgos'!$B$2:$B$70,$A26,'Planilla de Riesgos'!$H$2:$H$70),1),0) | D26: =SUMPRODUCT(MAX(('Planilla de Riesgos'!$B$2:$B$70=$A26)*'Planilla de Riesgos'!$H$2:$H$70)) | E26: =COUNTIFS('Planilla de Riesgos'!$B$2:$B$70,$A26,'Planilla de Riesgos'!$H$2:$H$70,">=11")
A27: Infraestructura | B27: =COUNTIF('Planilla de Riesgos'!$B$2:$B$70,$A27) | C27: =IFERROR(ROUND(AVERAGEIF('Planilla de Riesgos'!$B$2:$B$70,$A27,'Planilla de Riesgos'!$H$2:$H$70),1),0) | D27: =SUMPRODUCT(MAX(('Planilla de Riesgos'!$B$2:$B$70=$A27)*'Planilla de Riesgos'!$H$2:$H$70)) | E27: =COUNTIFS('Planilla de Riesgos'!$B$2:$B$70,$A27,'Planilla de Riesgos'!$H$2:$H$70,">=11")
A28: Seguridad | B28: =COUNTIF('Planilla de Riesgos'!$B$2:$B$70,$A28) | C28: =IFERROR(ROUND(AVERAGEIF('Planilla de Riesgos'!$B$2:$B$70,$A28,'Planilla de Riesgos'!$H$2:$H$70),1),0) | D28: =SUMPRODUCT(MAX(('Planilla de Riesgos'!$B$2:$B$70=$A28)*'Planilla de Riesgos'!$H$2:$H$70)) | E28: =COUNTIFS('Planilla de Riesgos'!$B$2:$B$70,$A28,'Planilla de Riesgos'!$H$2:$H$70,">=11")
A29: Legal / Datos personales | B29: =COUNTIF('Planilla de Riesgos'!$B$2:$B$70,$A29) | C29: =IFERROR(ROUND(AVERAGEIF('Planilla de Riesgos'!$B$2:$B$70,$A29,'Planilla de Riesgos'!$H$2:$H$70),1),0) | D29: =SUMPRODUCT(MAX(('Planilla de Riesgos'!$B$2:$B$70=$A29)*'Planilla de Riesgos'!$H$2:$H$70)) | E29: =COUNTIFS('Planilla de Riesgos'!$B$2:$B$70,$A29,'Planilla de Riesgos'!$H$2:$H$70,">=11")
A30: IA | B30: =COUNTIF('Planilla de Riesgos'!$B$2:$B$70,$A30) | C30: =IFERROR(ROUND(AVERAGEIF('Planilla de Riesgos'!$B$2:$B$70,$A30,'Planilla de Riesgos'!$H$2:$H$70),1),0) | D30: =SUMPRODUCT(MAX(('Planilla de Riesgos'!$B$2:$B$70=$A30)*'Planilla de Riesgos'!$H$2:$H$70)) | E30: =COUNTIFS('Planilla de Riesgos'!$B$2:$B$70,$A30,'Planilla de Riesgos'!$H$2:$H$70,">=11")
A31: Integraciones | B31: =COUNTIF('Planilla de Riesgos'!$B$2:$B$70,$A31) | C31: =IFERROR(ROUND(AVERAGEIF('Planilla de Riesgos'!$B$2:$B$70,$A31,'Planilla de Riesgos'!$H$2:$H$70),1),0) | D31: =SUMPRODUCT(MAX(('Planilla de Riesgos'!$B$2:$B$70=$A31)*'Planilla de Riesgos'!$H$2:$H$70)) | E31: =COUNTIFS('Planilla de Riesgos'!$B$2:$B$70,$A31,'Planilla de Riesgos'!$H$2:$H$70,">=11")
A32: Migración de datos | B32: =COUNTIF('Planilla de Riesgos'!$B$2:$B$70,$A32) | C32: =IFERROR(ROUND(AVERAGEIF('Planilla de Riesgos'!$B$2:$B$70,$A32,'Planilla de Riesgos'!$H$2:$H$70),1),0) | D32: =SUMPRODUCT(MAX(('Planilla de Riesgos'!$B$2:$B$70=$A32)*'Planilla de Riesgos'!$H$2:$H$70)) | E32: =COUNTIFS('Planilla de Riesgos'!$B$2:$B$70,$A32,'Planilla de Riesgos'!$H$2:$H$70,">=11")
A33: Usuario final | B33: =COUNTIF('Planilla de Riesgos'!$B$2:$B$70,$A33) | C33: =IFERROR(ROUND(AVERAGEIF('Planilla de Riesgos'!$B$2:$B$70,$A33,'Planilla de Riesgos'!$H$2:$H$70),1),0) | D33: =SUMPRODUCT(MAX(('Planilla de Riesgos'!$B$2:$B$70=$A33)*'Planilla de Riesgos'!$H$2:$H$70)) | E33: =COUNTIFS('Planilla de Riesgos'!$B$2:$B$70,$A33,'Planilla de Riesgos'!$H$2:$H$70,">=11")
... A36: Entregables académicos | B36: =COUNTIF('Planilla de Riesgos'!$B$2:$B$70,$A36) | C36: =IFERROR(ROUND(AVERAGEIF('Planilla de Riesgos'!$B$2:$B$70,$A36,'Planilla de Riesgos'!$H$2:$H$70),1),0) | D36: =SUMPRODUCT(MAX(('Planilla de Riesgos'!$B$2:$B$70=$A36)*'Planilla de Riesgos'!$H$2:$H$70)) | E36: =COUNTIFS('Planilla de Riesgos'!$B$2:$B$70,$A36,'Planilla de Riesgos'!$H$2:$H$70,">=11")
A37: Total general | B37: =SUM(B22:B36) | E37: =SUM(E22:E36)

Sheet Escalas y Criterios
A1: Escalas y criterios de evaluación de riesgos
A3: 1. Escala de probabilidad
A4: Valor | B4: Nivel | C4: Criterio aplicado en este proyecto
A5: 1 | B5: Raro | C5: Es improbable que ocurra durante las 18 semanas del proyecto
A6: 2 | B6: Poco probable | C6: Podría ocurrir una vez durante el proyecto
A7: 3 | B7: Posible | C7: Es razonable esperar que ocurra al menos una vez
A8: 4 | B8: Probable | C8: Es esperable que ocurra en más de un sprint
A9: 5 | B9: Casi seguro | C9: Ocurrirá salvo que se apliquen acciones preventivas
A12: 2. Escala de impacto
A13: Valor | B13: Nivel | C13: Criterio aplicado en este proyecto
A14: 1 | B14: Insignificante | C14: Sin efecto en el hito del sprint; se absorbe con el trabajo normal
A15: 2 | B15: Menor | C15: Atraso de hasta 2 días o retrabajo acotado a una historia de usuario
A16: 3 | B16: Moderado | C16: Atraso de hasta una semana o pérdida de una funcionalidad secundaria
A17: 4 | B17: Mayor | C17: Incumplimiento de un hito de sprint o pérdida de una funcionalidad comprometida
A18: 5 | B18: Crítico | C18: Compromete el objetivo general, la entrega final o la confianza de la agencia
A21: 3. Niveles de severidad (Probabilidad × Impacto)
A22: Rango | B22: Severidad | C22: Tratamiento requerido
A23: 1 a 5 | B23: Bajo | C23: Se acepta y se monitorea en la retrospectiva de cada sprint
A24: 6 a 10 | B24: Medio | C24: Requiere acciones de mitigación planificadas y un responsable asignado
A25: 11 a 15 | B25: Alto | C25: Requiere acciones de mitigación inmediatas y seguimiento semanal
A26: 16 a 25 | B26: Crítico | C26: Requiere plan de acción antes de continuar y escalamiento al docente guía
A29: 4. Estrategias de respuesta
A30: Estrategia | B30: Definición | C30: Cuándo se aplica
A31: Evitar | B31: Se modifica el plan o el diseño para eliminar la causa del riesgo | C31: Riesgos de severidad alta o crítica cuya causa está bajo control del equipo
A32: Mitigar | B32: Se reduce la probabilidad o el impacto mediante acciones preventivas | C32: Estrategia por defecto para la mayoría de los riesgos del proyecto
A33: Transferir | B33: Se traslada la responsabilidad a un tercero o a un servicio administrado | C33: Cuando existe un proveedor que asume la operación del componente
A34: Aceptar | B34: Se asume el riesgo y se define únicamente un plan de contingencia | C34: Riesgos de severidad baja cuyo costo de mitigación supera al beneficio
A37: 5. Categorías utilizadas
A38: Categoría | B38: Qué agrupa
A39: Alcance | B39: Riesgos asociados a la definición y el control de lo comprometido
A40: Stakeholders | B40: Riesgos derivados de la relación con la agencia y sus clientes
A41: Equipo | B41: Riesgos de disponibilidad, coordinación y competencias del equipo
A42: Planificación | B42: Riesgos de estimación, secuenciamiento y calendario
A43: Técnico | B43: Riesgos de desarrollo, diseño de datos, rendimiento y compatibilidad
A44: Infraestructura | B44: Riesgos de ambiente, despliegue, respaldo y disponibilidad
A45: Seguridad | B45: Riesgos de acceso, aislamiento de datos y vulnerabilidades
A46: Legal / Datos personales | B46: Riesgos normativos y de tratamiento de datos de terceros
A47: IA | B47: Riesgos propios del uso de modelos generativos
A48: Integraciones | B48: Riesgos de dependencia de servicios y APIs externas
A49: Migración de datos | B49: Riesgos del traspaso de información desde las herramientas actuales
...
