Workbook

Sheet Casos de Prueba
A1: ID | B1: Módulo | C1: Sprint | D1: Caso de prueba | E1: Precondición | F1: Pasos | G1: Resultado esperado | H1: Tipo | I1: Prioridad | J1: Estado de ejecución | K1: Fecha ejecución | L1: Ejecutado por | M1: Defecto asociado
A2: CP-001 | B2: A. Sitio corporativo | C2: Sprint 1 | D2: Carga y navegación del sitio público | E2: Sitio desplegado en el ambiente de pruebas | F2: 1. Acceder a la URL del sitio. 2. Navegar por todas las secciones del menú. | G2: Todas las secciones cargan sin error. No se presentan enlaces rotos ni recursos faltantes. | H2: Funcional | I2: Alta | J2: Pendiente
A3: CP-002 | B3: A. Sitio corporativo | C3: Sprint 1 | D3: Envío del formulario de contacto con datos válidos | E3: Sitio publicado y servicio de correo configurado | F3: 1. Completar nombre, correo, teléfono, rubro y mensaje. 2. Enviar el formulario. | G3: Se muestra confirmación al visitante. Se crea un prospecto en el módulo comercial. Se envía el correo de aviso a la agencia. | H3: Funcional | I3: Alta | J3: Pendiente
A4: CP-003 | B4: A. Sitio corporativo | C4: Sprint 1 | D4: Validación de campos obligatorios | E4: Formulario de contacto disponible | F4: 1. Enviar el formulario con los campos vacíos. | G4: El sistema impide el envío. Se indica con claridad cada campo obligatorio faltante. | H4: Funcional | I4: Alta | J4: Pendiente
A5: CP-004 | B5: A. Sitio corporativo | C5: Sprint 1 | D5: Rechazo de correo con formato inválido | E5: Formulario de contacto disponible | F5: 1. Ingresar un correo sin arroba o sin dominio. 2. Enviar el formulario. | G5: Se rechaza el envío y se informa el formato esperado. No se crea ningún prospecto. | H5: Funcional | I5: Media | J5: Pendiente
A6: CP-005 | B6: A. Sitio corporativo | C6: Sprint 1 | D6: Publicación de contenido desde el CMS | E6: Usuario administrador autenticado | F6: 1. Crear una entrada con título, cuerpo e imagen. 2. Guardar como borrador y luego publicar. | G6: La entrada se muestra en el sitio público tras publicarse. Como borrador no es visible para visitantes. | H6: Funcional | I6: Alta | J6: Pendiente
A7: CP-006 | B7: A. Sitio corporativo | C7: Sprint 1 | D7: Edición y despublicación de contenido | E7: Existe una entrada publicada | F7: 1. Editar el título y el cuerpo. 2. Guardar y luego despublicar. | G7: Los cambios se reflejan en el sitio. Al despublicar, la entrada deja de ser accesible públicamente. | H7: Funcional | I7: Media | J7: Pendiente
A8: CP-007 | B8: A. Sitio corporativo | C8: Sprint 1 | D8: Acceso al CMS sin autenticación | E8: Sesión cerrada | F8: 1. Acceder directamente a la URL del CMS. | G8: Se redirige al inicio de sesión. No se expone contenido ni estructura del panel. | H8: Seguridad | I8: Alta | J8: Pendiente
A9: CP-008 | B9: A. Sitio corporativo | C9: Sprint 1 | D9: Sanitización de contenido con etiquetas de script | E9: Usuario administrador autenticado | F9: 1. Ingresar etiquetas HTML y un script en un campo de texto. 2. Guardar y visualizar en el sitio público. | G9: El contenido se almacena sanitizado. No se ejecuta ningún script en el navegador del visitante. | H9: Seguridad | I9: Alta | J9: Pendiente
A10: CP-009 | B10: A. Sitio corporativo | C10: Sprint 1 | D10: Metadatos de posicionamiento por página | E10: Páginas creadas en el CMS | F10: 1. Definir título y descripción para una página. 2. Inspeccionar el código fuente publicado. | G10: Los metadatos definidos aparecen correctamente en el documento publicado. | H10: Funcional | I10: Media | J10: Conforme | K10: 46314 | L10: Felipe Gutiérrez
A11: CP-010 | B11: A. Sitio corporativo | C11: Sprint 1 | D11: Visualización responsiva en dispositivo móvil | E11: Sitio publicado | F11: 1. Abrir el sitio en pantallas de 360, 768 y 1440 píxeles de ancho. | G11: El contenido se adapta sin desbordes ni superposiciones. Los elementos interactivos son accionables con el dedo. | H11: Compatibilidad | I11: Alta | J11: Pendiente
A12: CP-011 | B12: B. Autenticación y acceso | C12: Sprint 1 | D12: Inicio de sesión con credenciales válidas | E12: Usuario administrador registrado | F12: 1. Ingresar correo y contraseña correctos. 2. Confirmar. | G12: Se accede al panel correspondiente al rol. Se registra el acceso en la bitácora. | H12: Funcional | I12: Alta | J12: Pendiente
A13: CP-012 | B13: B. Autenticación y acceso | C13: Sprint 1 | D13: Inicio de sesión con credenciales inválidas | E13: Usuario registrado | F13: 1. Ingresar una contraseña incorrecta. 2. Confirmar. | G13: Se deniega el acceso. El mensaje no revela si el error está en el correo o en la contraseña. | H13: Seguridad | I13: Alta | J13: Pendiente
A14: CP-013 | B14: B. Autenticación y acceso | C14: Sprint 1 | D14: Bloqueo tras intentos fallidos sucesivos | E14: Usuario registrado | F14: 1. Intentar ingresar con contraseña incorrecta cinco veces consecutivas. | G14: La cuenta se bloquea temporalmente. Se informa al usuario el tiempo de espera. | H14: Seguridad | I14: Alta | J14: Pendiente
A15: CP-014 | B15: B. Autenticación y acceso | C15: Sprint 1 | D15: Recuperación de contraseña | E15: Usuario registrado con correo válido | F15: 1. Solicitar recuperación. 2. Abrir el enlace recibido. 3. Definir una contraseña nueva. | G15: Se recibe el correo con un enlace de un solo uso. El enlace expira tras usarse o vencer su plazo. | H15: Funcional | I15: Alta | J15: Pendiente
A16: CP-015 | B16: B. Autenticación y acceso | C16: Sprint 1 | D16: Rechazo de contraseñas débiles | E16: Formulario de registro o cambio disponible | F16: 1. Intentar definir una contraseña de menos de ocho caracteres y sin complejidad. | G16: Se rechaza y se indica la política de contraseñas vigente. | H16: Seguridad | I16: Media | J16: Pendiente
A17: CP-016 | B17: B. Autenticación y acceso | C17: Sprint 1 | D17: Segundo factor en cuenta de administración | E17: Cuenta de administración con segundo factor habilitado | F17: 1. Iniciar sesión con credenciales correctas. 2. Omitir el segundo factor. | G17: No se concede acceso hasta validar el segundo factor. | H17: Seguridad | I17: Alta | J17: Pendiente
A18: CP-017 | B18: B. Autenticación y acceso | C18: Sprint 1 | D18: Cierre de sesión e invalidación del token | E18: Sesión activa | F18: 1. Cerrar sesión. 2. Reutilizar el token anterior contra la API. | G18: El token queda invalidado. La API responde con acceso denegado. | H18: Seguridad | I18: Alta | J18: Pendiente
A19: CP-018 | B19: B. Autenticación y acceso | C19: Sprint 1 | D19: Expiración de sesión por inactividad | E19: Sesión activa | F19: 1. Permanecer inactivo hasta alcanzar el tiempo de expiración. | G19: Se muestra un aviso previo a la expiración. Al expirar, se solicita autenticarse nuevamente sin perder el borrador en curso. | H19: Funcional | I19: Media | J19: Pendiente
A20: CP-019 | B20: B. Autenticación y acceso | C20: Sprint 1 | D20: Usuario cliente sin acceso al módulo de administración | E20: Usuario cliente autenticado | F20: 1. Acceder a la URL del panel de administración. | G20: Se deniega el acceso con el mensaje correspondiente. El intento queda registrado en la bitácora. | H20: Seguridad | I20: Alta | J20: Conforme | K20: 46314 | L20: Felipe Gutiérrez
A21: CP-020 | B21: B. Autenticación y acceso | C21: Sprint 1 | D21: Acceso por URL a un recurso de otro cliente | E21: Dos clientes con datos propios cargados | F21: 1. Autenticarse como cliente A. 2. Solicitar por URL un recurso identificado del cliente B. | G21: Se deniega el acceso. No se revela la existencia ni el contenido del recurso. | H21: Seguridad | I21: Alta | J21: Pendiente
A22: CP-021 | B22: B. Autenticación y acceso | C22: Sprint 1 | D22: Manipulación del identificador de cliente en la API | E22: Dos clientes con datos propios cargados | F22: 1. Autenticarse como cliente A. 2. Modificar el identificador de cliente en la petición a la API. | G22: La API ignora el identificador enviado y responde solo con datos del cliente autenticado. | H22: Seguridad | I22: Alta | J22: Pendiente
A23: CP-022 | B23: B. Autenticación y acceso | C23: Sprint 1 | D23: Registro de auditoría de acciones administrativas | E23: Usuario administrador autenticado | F23: 1. Crear, modificar y eliminar un registro. 2. Consultar la bitácora. | G23: Cada acción queda registrada con usuario, fecha, hora y tipo de operación. | H23: Seguridad | I23: Media | J23: Pendiente
A24: CP-023 | B24: C. Gestión comercial | C24: Sprint 2 | D24: Creación de un prospecto con datos válidos | E24: Usuario de la agencia autenticado | F24: 1. Completar el formulario de nuevo prospecto. 2. Guardar. | G24: El prospecto se crea en estado inicial y aparece en el listado. | H24: Funcional | I24: Alta | J24: Pendiente
A25: CP-024 | B25: C. Gestión comercial | C25: Sprint 2 | D25: Validación de RUT inválido | E25: Formulario de prospecto disponible | F25: 1. Ingresar un RUT con dígito verificador incorrecto. 2. Guardar. | G25: Se rechaza el guardado y se informa el error de validación. | H25: Funcional | I25: Media | J25: Pendiente
A26: CP-025 | B26: C. Gestión comercial | C26: Sprint 2 | D26: Alerta de prospecto duplicado | E26: Existe un prospecto con el correo indicado | F26: 1. Crear un prospecto nuevo con el mismo correo. 2. Guardar. | G26: El sistema advierte del posible duplicado antes de confirmar la creación. | H26: Funcional | I26: Media | J26: Pendiente
A27: CP-026 | B27: C. Gestión comercial | C27: Sprint 2 | D27: Edición de prospecto con registro de cambios | E27: Prospecto existente | F27: 1. Modificar los datos de contacto. 2. Guardar y revisar el historial. | G27: Los cambios se guardan. El historial registra qué se modificó, quién y cuándo. | H27: Funcional | I27: Media | J27: Pendiente
A28: CP-027 | B28: C. Gestión comercial | C28: Sprint 2 | D28: Eliminación y recuperación de un prospecto | E28: Prospecto existente | F28: 1. Eliminar el prospecto. 2. Recuperarlo desde la papelera. | G28: Se solicita confirmación antes de eliminar. El registro se recupera íntegro con su historial. | H28: Funcional | I28: Alta | J28: Pendiente
A29: CP-028 | B29: C. Gestión comercial | C29: Sprint 2 | D29: Búsqueda y filtrado de prospectos | E29: Al menos cincuenta prospectos cargados | F29: 1. Filtrar por estado del embudo. 2. Buscar por nombre o correo. | G29: Los resultados corresponden exactamente al criterio aplicado. | H29: Funcional | I29: Media | J29: Pendiente
A30: CP-029 | B30: C. Gestión comercial | C30: Sprint 2 | D30: Registro de interacción en la ficha | E30: Prospecto existente | F30: 1. Registrar una llamada con fecha y observación. 2. Guardar. | G30: La interacción se muestra en el historial ordenada cronológicamente. | H30: Funcional | I30: Media | J30: Pendiente
A31: CP-030 | B31: C. Gestión comercial | C31: Sprint 2 | D31: Creación de una cotización | E31: Prospecto existente y catálogo de servicios cargado | F31: 1. Iniciar una cotización. 2. Seleccionar servicios y cantidades. 3. Guardar como borrador. | G31: La cotización queda asociada al prospecto en estado borrador. | H31: Funcional | I31: Alta | J31: Pendiente
A32: CP-031 | B32: C. Gestión comercial | C32: Sprint 2 | D32: Cálculo del total de la cotización | E32: Cotización en edición | F32: 1. Agregar tres servicios con distintas cantidades. 2. Aplicar un descuento porcentual. | G32: El total corresponde a la suma de los subtotales menos el descuento, con el impuesto aplicado según la configuración. | H32: Funcional | I32: Alta | J32: Pendiente
... A78: CP-077 | B78: D. Portal de clientes | C78: Sprint 3 | D78: PC-SOL-01 - Creación y seguimiento de una solicitud del cliente | E78: Cliente autenticado y portal operativo. | F78: 1. Crear una solicitud indicando asunto y detalle. 2. Adjuntar un archivo si corresponde. 3. Enviar. 4. Consultar el estado de la solicitud. | G78: La solicitud se registra correctamente, queda asociada al cliente, el archivo se almacena cuando corresponde y el cliente puede consultar el estado de su solicitud. | H78: Funcional | I78: Alta | J78: Pendiente

Sheet Resumen y Cobertura
A1: Resumen y cobertura del Plan de Pruebas
A3: 1. Resumen por módulo
A4: Módulo | B4: N.º de casos | C4: Prioridad alta | D4: Ejecutados (conforme) | E4: % avance
A5: A. Sitio corporativo | B5: =COUNTIF('Casos de Prueba'!$B$2:$B$78,$A5) | C5: =COUNTIFS('Casos de Prueba'!$B$2:$B$78,$A5,'Casos de Prueba'!$I$2:$I$78,"Alta") | D5: =COUNTIFS('Casos de Prueba'!$B$2:$B$78,$A5,'Casos de Prueba'!$J$2:$J$78,"Conforme") | E5: =IFERROR(D5/B5,0)
A6: B. Autenticación y acceso | B6: =COUNTIF('Casos de Prueba'!$B$2:$B$78,$A6) | C6: =COUNTIFS('Casos de Prueba'!$B$2:$B$78,$A6,'Casos de Prueba'!$I$2:$I$78,"Alta") | D6: =COUNTIFS('Casos de Prueba'!$B$2:$B$78,$A6,'Casos de Prueba'!$J$2:$J$78,"Conforme") | E6: =IFERROR(D6/B6,0)
A7: C. Gestión comercial | B7: =COUNTIF('Casos de Prueba'!$B$2:$B$78,$A7) | C7: =COUNTIFS('Casos de Prueba'!$B$2:$B$78,$A7,'Casos de Prueba'!$I$2:$I$78,"Alta") | D7: =COUNTIFS('Casos de Prueba'!$B$2:$B$78,$A7,'Casos de Prueba'!$J$2:$J$78,"Conforme") | E7: =IFERROR(D7/B7,0)
A8: D. Portal de clientes | B8: =COUNTIF('Casos de Prueba'!$B$2:$B$78,$A8) | C8: =COUNTIFS('Casos de Prueba'!$B$2:$B$78,$A8,'Casos de Prueba'!$I$2:$I$78,"Alta") | D8: =COUNTIFS('Casos de Prueba'!$B$2:$B$78,$A8,'Casos de Prueba'!$J$2:$J$78,"Conforme") | E8: =IFERROR(D8/B8,0)
A9: E. Métricas y dashboards | B9: =COUNTIF('Casos de Prueba'!$B$2:$B$78,$A9) | C9: =COUNTIFS('Casos de Prueba'!$B$2:$B$78,$A9,'Casos de Prueba'!$I$2:$I$78,"Alta") | D9: =COUNTIFS('Casos de Prueba'!$B$2:$B$78,$A9,'Casos de Prueba'!$J$2:$J$78,"Conforme") | E9: =IFERROR(D9/B9,0)
A10: F. Funciones de IA | B10: =COUNTIF('Casos de Prueba'!$B$2:$B$78,$A10) | C10: =COUNTIFS('Casos de Prueba'!$B$2:$B$78,$A10,'Casos de Prueba'!$I$2:$I$78,"Alta") | D10: =COUNTIFS('Casos de Prueba'!$B$2:$B$78,$A10,'Casos de Prueba'!$J$2:$J$78,"Conforme") | E10: =IFERROR(D10/B10,0)
A11: G. Notificaciones y correo | B11: =COUNTIF('Casos de Prueba'!$B$2:$B$78,$A11) | C11: =COUNTIFS('Casos de Prueba'!$B$2:$B$78,$A11,'Casos de Prueba'!$I$2:$I$78,"Alta") | D11: =COUNTIFS('Casos de Prueba'!$B$2:$B$78,$A11,'Casos de Prueba'!$J$2:$J$78,"Conforme") | E11: =IFERROR(D11/B11,0)
A12: H. Pruebas no funcionales | B12: =COUNTIF('Casos de Prueba'!$B$2:$B$78,$A12) | C12: =COUNTIFS('Casos de Prueba'!$B$2:$B$78,$A12,'Casos de Prueba'!$I$2:$I$78,"Alta") | D12: =COUNTIFS('Casos de Prueba'!$B$2:$B$78,$A12,'Casos de Prueba'!$J$2:$J$78,"Conforme") | E12: =IFERROR(D12/B12,0)
A13: Total | B13: =COUNTIF('Casos de Prueba'!$B$2:$B$78,$A13) | C13: =COUNTIFS('Casos de Prueba'!$B$2:$B$78,$A13,'Casos de Prueba'!$I$2:$I$78,"Alta") | D13: =COUNTIFS('Casos de Prueba'!$B$2:$B$78,$A13,'Casos de Prueba'!$J$2:$J$78,"Conforme") | E13: =IFERROR(D13/B13,0)
A15: 2. Resumen por tipo de prueba
A16: Tipo | B16: N.º de casos | C16: Ejecutados (conforme) | D16: % avance
A17: Funcional | B17: =COUNTIF('Casos de Prueba'!$H$2:$H$78,$A17) | C17: =COUNTIFS('Casos de Prueba'!$H$2:$H$78,$A17,'Casos de Prueba'!$J$2:$J$78,"Conforme") | D17: =IFERROR(C17/B17,0)
A18: Seguridad | B18: =COUNTIF('Casos de Prueba'!$H$2:$H$78,$A18) | C18: =COUNTIFS('Casos de Prueba'!$H$2:$H$78,$A18,'Casos de Prueba'!$J$2:$J$78,"Conforme") | D18: =IFERROR(C18/B18,0)
A19: Usabilidad | B19: =COUNTIF('Casos de Prueba'!$H$2:$H$78,$A19) | C19: =COUNTIFS('Casos de Prueba'!$H$2:$H$78,$A19,'Casos de Prueba'!$J$2:$J$78,"Conforme") | D19: =IFERROR(C19/B19,0)
A20: Compatibilidad | B20: =COUNTIF('Casos de Prueba'!$H$2:$H$78,$A20) | C20: =COUNTIFS('Casos de Prueba'!$H$2:$H$78,$A20,'Casos de Prueba'!$J$2:$J$78,"Conforme") | D20: =IFERROR(C20/B20,0)
A21: Rendimiento | B21: =COUNTIF('Casos de Prueba'!$H$2:$H$78,$A21) | C21: =COUNTIFS('Casos de Prueba'!$H$2:$H$78,$A21,'Casos de Prueba'!$J$2:$J$78,"Conforme") | D21: =IFERROR(C21/B21,0)
A22: Recuperación | B22: =COUNTIF('Casos de Prueba'!$H$2:$H$78,$A22) | C22: =COUNTIFS('Casos de Prueba'!$H$2:$H$78,$A22,'Casos de Prueba'!$J$2:$J$78,"Conforme") | D22: =IFERROR(C22/B22,0)
A24: 3. Resumen por prioridad
A25: Prioridad | B25: N.º de casos | C25: Ejecutados (conforme) | D25: % avance
A26: Alta | B26: =COUNTIF('Casos de Prueba'!$I$2:$I$78,$A26) | C26: =COUNTIFS('Casos de Prueba'!$I$2:$I$78,$A26,'Casos de Prueba'!$J$2:$J$78,"Conforme") | D26: =IFERROR(C26/B26,0)
A27: Media | B27: =COUNTIF('Casos de Prueba'!$I$2:$I$78,$A27) | C27: =COUNTIFS('Casos de Prueba'!$I$2:$I$78,$A27,'Casos de Prueba'!$J$2:$J$78,"Conforme") | D27: =IFERROR(C27/B27,0)
A28: Baja | B28: =COUNTIF('Casos de Prueba'!$I$2:$I$78,$A28) | C28: =COUNTIFS('Casos de Prueba'!$I$2:$I$78,$A28,'Casos de Prueba'!$J$2:$J$78,"Conforme") | D28: =IFERROR(C28/B28,0)
A30: 4. Resumen general de ejecución
A31: Estado | B31: N.º de casos | C31: % del total
A32: Pendiente | B32: =COUNTIF('Casos de Prueba'!$J$2:$J$78,$A32) | C32: =IFERROR(B32/78,0)
A33: Conforme | B33: =COUNTIF('Casos de Prueba'!$J$2:$J$78,$A33) | C33: =IFERROR(B33/78,0)
A34: No conforme | B34: =COUNTIF('Casos de Prueba'!$J$2:$J$78,$A34) | C34: =IFERROR(B34/78,0)
A35: Bloqueado | B35: =COUNTIF('Casos de Prueba'!$J$2:$J$78,$A35) | C35: =IFERROR(B35/78,0)
A38: 5. Matriz de trazabilidad (requerimiento → casos de prueba)
A39: Requerimiento | B39: Descripción | C39: Casos de prueba asociados | D39: Cobertura
A40: RF-01 | B40: Sitio corporativo con gestor de contenidos y posicionamiento. | C40: CP-001, CP-005, CP-006, CP-009, CP-010 | D40: Cubierto
A41: RF-02 | B41: Captura de prospectos desde el sitio público. | C41: CP-002, CP-003, CP-004, CP-023 | D41: Cubierto
A42: RF-03 | B42: Gestión y seguimiento de prospectos. | C42: CP-023 a CP-029 | D42: Cubierto
A43: RF-04 | B43: Cotizador dinámico con cálculo automático. | C43: CP-030, CP-031, CP-032, CP-036 | D43: Cubierto
A44: RF-05 | B44: Envío y seguimiento del estado de las cotizaciones. | C44: CP-033, CP-034, CP-063 | D44: Cubierto
A45: RF-06 | B45: Conversión de prospecto a cliente. | C45: CP-035 | D45: Cubierto
A46: RF-07 | B46: Calendario editorial por cliente. | C46: CP-038, CP-040, CP-049 | D46: Cubierto
...
