Workbook

Sheet Historias de Usuario
B1: Desarrollo ágil: Pila de Producto (Product Backlog)
B2: Elaborado por: pmoinformatica.com
B3: Proyecto: Plataforma Cosmopolitan (Capstone) · Cliente: Agencia Cosmopolitan · Equipo: Esteban Morales, Christian Cuadra y Felipe Gutiérrez
B4: Identificador (ID) de la Historia | C4: Enunciado de la Historia | D4: Alias | E4: Estado | F4: Dimensión / Esfuerzo | G4: Iteración (Sprint) | H4: Prioridad | I4: Comentarios | J4: Criterios de aceptación | K4: Casos de prueba
B5: PC-TEC-01 | C5: Como equipo de desarrollo, necesito un repositorio versionado y un entorno reproducible mediante contenedores, con la finalidad de trabajar de forma ordenada y que cualquier integrante pueda levantar el proyecto de la misma forma. | D5: Repositorio y entorno base | E5: Hecho | F5: 3 | G5: Sprint 0 | H5: Alta | I5: T · Habilitadora · Deja listo el repositorio y un entorno con contenedores para que los tres integrantes trabajen de la misma forma. Corresponde a la actividad de configuración inicial de la Carta Gantt (Sprint 0). | J5: 1. El repositorio tiene ramas definidas y README con instrucciones de instalación. 2. Cualquier integrante levanta el proyecto con contenedores siguiendo el README, sin pasos manuales adicionales. 3. No hay credenciales ni claves versionadas en el repositorio. | K5: —
B6: PC-AUT-01 | C6: Como usuario registrado (administradora, colaboradora o cliente), necesito iniciar y cerrar sesión con mis credenciales, con la finalidad de acceder de forma segura solo a lo que me corresponde. | D6: Inicio y cierre de sesión | E6: Hecho | F6: 3 | G6: Sprint 1 | H6: Alta | I6: T · Obj. 1 · Inicio y cierre de sesión con Firebase Authentication (ver Documento de arquitectura). Es la base de todas las historias: sin sesión no hay roles ni aislamiento. Se prueba con CP-011, CP-012 y CP-017. | J6: 1. Con credenciales válidas, el usuario accede al panel que corresponde a su rol. 2. Con credenciales inválidas se niega el acceso sin indicar si falló el correo o la contraseña. 3. Al cerrar sesión, la sesión queda invalidada y no se puede volver con el botón atrás. 4. La sesión expira tras un período de inactividad. | K6: CP-011, CP-012, CP-013, CP-014, CP-015, CP-017, CP-018
B7: PC-AUT-02 | C7: Como administradora, necesito activar la verificación en dos pasos (2FA) en mi cuenta, con la finalidad de proteger el acceso a la gestión completa de la agencia. | D7: 2FA para administradoras | E7: Hecho | F7: 3 | G7: Sprint 1 | H7: Alta | I7: E1 · Obj. 1 · Protege las cuentas con más poder (administradoras) con un segundo factor además de la contraseña. Ver RNF-01 en la Especificación de requerimientos. Se prueba con CP-016. | J7: 1. La administradora puede activar el segundo factor desde su cuenta. 2. Con 2FA activo, no se accede solo con la contraseña. 3. Un código incorrecto o vencido niega el acceso. | K7: CP-016
B8: PC-AUT-03 | C8: Como administradora, necesito crear y gestionar usuarios asignándoles un rol (administradora, colaboradora, cliente aprobador o cliente lector), con la finalidad de controlar quién puede ver y hacer qué dentro de la plataforma. | D8: Gestión de usuarios y roles | E8: Hecho | F8: 5 | G8: Sprint 1 | H8: Alta | I8: E1 · Obj. 1 · Permite a la administradora dar de alta usuarios con su rol. Los roles definidos aquí determinan qué puede ver y hacer cada usuario en el resto de la plataforma. | J8: 1. La administradora crea usuarios asignando uno de los cuatro roles. 2. Puede editar el rol o desactivar un usuario; un usuario desactivado no puede iniciar sesión. 3. Solo la administradora accede a la gestión de usuarios. | K8: CP-019
B9: PC-AUT-04 | C9: Como colaboradora, necesito acceder únicamente a la información de los clientes que me fueron asignados, con la finalidad de trabajar sin exponer datos de otros clientes. | D9: Colaboradora solo ve sus clientes | E9: Hecho | F9: 8 | G9: Sprint 2 | H9: Alta | I9: E2 · Obj. 1 · Una colaboradora solo trabaja con los clientes que le asignan; los demás deben quedar invisibles para ella. En el Sprint 1 el cliente es un registro mínimo (nombre); la ficha completa llega con PC-CLI-02 (Sprint 2). | J9: 1. La colaboradora solo ve en listas y búsquedas los clientes que tiene asignados. 2. Si intenta abrir un cliente no asignado (por URL o API), el sistema niega el acceso. 3. Al quitarle un cliente, deja de verlo de inmediato. | K9: CP-020, CP-021
B10: PC-AUT-05 | C10: Como cliente (aprobador o lector), necesito ver únicamente la información de mi empresa, con la finalidad de tener certeza de que mis datos no son visibles para otros clientes. | D10: Cliente solo ve su empresa | E10: Hecho | F10: 8 | G10: Sprint 2 | H10: Alta | I10: E3 (y E4) · Obj. 1 y 9 · Es el requisito más crítico del proyecto: ningún cliente puede ver datos de otro. El filtro se aplica en la capa intermedia (API) y no en la pantalla. Se prueba con PC-TEC-04 (CP-020 y CP-021). | J10: 1. El cliente solo ve información de su propia empresa en todas las pantallas. 2. Cambiar el identificador en la URL o en la API devuelve acceso denegado. 3. El filtro por empresa se aplica en la API, no solo en la interfaz. | K10: CP-019, CP-020, CP-021
B11: PC-AUT-06 | C11: Como administradora, necesito que las acciones sensibles queden registradas (quién, qué, sobre qué y cuándo), con la finalidad de tener trazabilidad de los cambios realizados en la plataforma. | D11: Log de auditoría | E11: Hecho | F11: 5 | G11: Sprint 1 | H11: Media | I11: E1 · Obj. 1 · Deja un registro de quién hizo qué y cuándo en las acciones sensibles (usuarios, roles y cambios de catálogo). Responde al riesgo R-38 de la Planilla de riesgos. Se prueba con CP-022. | J11: 1. Las acciones sensibles (usuarios, roles, catálogo) quedan registradas con quién, qué, sobre qué y cuándo. 2. El registro no puede editarse ni borrarse desde la plataforma. 3. La administradora puede consultar el registro filtrando por usuario o fecha. | K11: CP-022
B12: PC-CAT-01 | C12: Como administradora, necesito crear, editar y desactivar los planes mensuales con sus entregables incluidos, con la finalidad de mantener el catálogo actualizado sin depender de un desarrollador. | D12: Catálogo de planes | E12: Hecho | F12: 5 | G12: Sprint 1 | H12: Alta | I12: E1 · Obj. 3 · Permite crear y editar los planes mensuales sin pedir cambios al equipo de desarrollo. Los planes del catálogo alimentan el sitio público, el cotizador (Sprint 2) y el control de cuota (Sprint 3). | J12: 1. La administradora crea, edita y desactiva planes con nombre, precio y entregables incluidos. 2. Un plan desactivado deja de mostrarse en el sitio y en el cotizador, pero se conserva en los clientes que ya lo tienen. 3. Los cambios quedan en el registro de auditoría. | K12: —
B13: PC-CAT-02 | C13: Como administradora, necesito crear, editar y desactivar los servicios que se contratan por separado, con la finalidad de ofrecerlos en el sitio y en las cotizaciones sin intervención en código. | D13: Catálogo de servicios | E13: Hecho | F13: 3 | G13: Sprint 1 | H13: Media | I13: E1 · Obj. 3 · Igual que los planes, pero para los servicios que se contratan por separado (por ejemplo, gestión de pauta o landing). Se muestran en el sitio y se pueden agregar a una cotización. | J13: 1. La administradora crea, edita y desactiva servicios con nombre y precio. 2. Los servicios activos se muestran en el sitio y pueden agregarse a una cotización. 3. Un servicio desactivado deja de ofrecerse sin afectar cotizaciones anteriores. | K13: —
B14: PC-WEB-01 | C14: Como visitante, necesito conocer los planes y servicios de la agencia en su sitio público, con la finalidad de decidir si quiero contratarla. | D14: Sitio muestra planes y servicios | E14: Hecho | F14: 5 | G14: Sprint 1 | H14: Alta | I14: E5 · Obj. 2 (indirecto) · Vista pública de los planes y servicios del catálogo: si la administradora cambia el catálogo, el sitio se actualiza solo. Es parte de la Fase 1 (sitio corporativo). | J14: 1. El sitio muestra los planes y servicios activos del catálogo. 2. Un cambio en el catálogo se refleja en el sitio sin modificar código. 3. La página carga sin errores ni enlaces rotos. | K14: CP-001
B15: PC-WEB-02 | C15: Como administradora, necesito editar los contenidos del sitio (textos, imágenes y secciones) desde un CMS, con la finalidad de mantener el sitio actualizado sin tocar código. | D15: CMS del sitio | E15: Hecho | F15: 8 | G15: Sprint 1 | H15: Alta | I15: E1 · Obj. 2 (indirecto) · CMS: la administradora edita textos, imágenes y secciones del sitio sin tocar código. Se prueba con CP-005 y CP-006; el acceso sin sesión, con CP-007. | J15: 1. La administradora crea, edita, publica y despublica contenidos del sitio desde el CMS. 2. Un borrador no se ve en el sitio público hasta que se publica. 3. El CMS no es accesible sin sesión y el contenido ingresado se guarda sanitizado. | K15: CP-005, CP-006, CP-007, CP-008
B16: PC-WEB-03 | C16: Como visitante, necesito navegar el sitio cómodamente desde mi celular y con teclado, con la finalidad de acceder a la información sin dificultades, sin importar el dispositivo. | D16: Sitio responsivo y accesible | E16: Hecho | F16: 3 | G16: Sprint 1 | H16: Media | I16: E5 · RNF-04 · Que el sitio se vea y funcione bien en celular (desde 360 px), se pueda recorrer con teclado y respete el manual de marca. Se prueba con CP-010. | J16: 1. El sitio se ve sin desbordes en pantallas de 360, 768 y 1440 px. 2. Todas las secciones se pueden recorrer con teclado. 3. Colores y tipografías respetan el manual de marca. | K16: CP-010
... B51: PC-AUT-07 | C51: Como administradora, necesito dar acceso al portal a las personas de un cliente ya convertido, enviándoles una invitación por correo para que activen su cuenta definiendo su propia contraseña, con la finalidad de que solo entren clientes con plan contratado y sin que la agencia conozca sus contraseñas. | D51: Activación de cuenta del cliente | E51: En Proceso | F51: 5 | G51: Sprint 2 | H51: Alta | I51: E1 · Obj. 1 y 9 · Mantiene el registro cerrado (PC-AUT-01, validado por la agencia en la Sprint Review S1): no hay autoregistro; la cuenta la crea la administradora desde la ficha del cliente cuando se confirma el pago (fuera de la plataforma) y la persona la activa desde un enlace por correo. Historia nueva, detectada por el equipo al revisar el flujo prospecto → cliente. Depende de PC-AUT-03 y PC-CLI-01. El envío real del correo depende de configurar el proveedor de correo (tarjeta «Configurar envío de correos»). Incorporada al Sprint 2 el 22 oct 2026 por decisión del equipo (5 pts es una propuesta del equipo). Pendiente: presentar el flujo a la agencia (aún no lo conoce) y validarlo con ella. | J51: 1. Desde la ficha del cliente, la administradora crea la cuenta indicando nombre, correo y rol (Cliente aprobador o Cliente lector); la cuenta queda asociada a esa empresa. No existe registro público. 2. Al crearla se envía un correo con un enlace personal de activación; la cuenta queda «Pendiente de activación» y no puede iniciar sesión hasta activarse. 3. Desde el enlace, la persona define su contraseña (cumpliendo la política de contraseñas) y entra directamente al portal de su empresa. 4. El enlace sirve una sola vez y vence a los 3 días; la administradora puede reenviar la invitación o copiar el enlace. 5. Solo la administradora puede dar acceso; la creación, el reenvío y la activación quedan en el registro de auditoría. | K51: CP-015 · casos nuevos de activación por agregar al Plan de Pruebas

Sheet Épicas y resumen
B1: Épicas, resumen por sprint y supuestos
B2: Complemento del Product Backlog · Plataforma Cosmopolitan
B4: 1. Épicas
B5: Código | C5: Épica (rol) | D5: Necesidad de fondo | E5: Objetivos específicos | F5: N.º de historias | G5: Puntos
B6: E1 | C6: Administradora — gestionar la agencia | D6: Necesito centralizar la gestión comercial y operativa de la agencia, para dejar de depender de Notion y de canales informales. | E6: 2, 3, 4, 6, 7, 8 | F6: =COUNTIF('Historias de Usuario'!$I$5:$I$60,"E1*") | G6: =SUMIF('Historias de Usuario'!$I$5:$I$60,"E1*",'Historias de Usuario'!$F$5:$F$60)
B7: E2 | C7: Colaboradora — producir contenido | D7: Necesito acceder solo a la información de mis clientes asignados, para trabajar sin exponer datos de otros clientes. | E7: 1, 5 | F7: =COUNTIF('Historias de Usuario'!$I$5:$I$60,"E2*") | G7: =SUMIF('Historias de Usuario'!$I$5:$I$60,"E2*",'Historias de Usuario'!$F$5:$F$60)
B8: E3 | C8: Cliente aprobador — aprobar contenido | D8: Necesito revisar y aprobar el contenido de mi marca desde un solo lugar, para tener trazabilidad de lo que autoricé. | E8: 1, 5, 9 | F8: =COUNTIF('Historias de Usuario'!$I$5:$I$60,"E3*") | G8: =SUMIF('Historias de Usuario'!$I$5:$I$60,"E3*",'Historias de Usuario'!$F$5:$F$60)
B9: E4 | C9: Cliente lector — estar informada | D9: Necesito visualizar el estado de mi plan y mis métricas, para estar al tanto sin gestionar directamente el contenido. | E9: 4, 6, 9 | F9: =COUNTIF('Historias de Usuario'!$I$5:$I$60,"E4*") | G9: =SUMIF('Historias de Usuario'!$I$5:$I$60,"E4*",'Historias de Usuario'!$F$5:$F$60)
B10: E5 | C10: Prospecto / visitante — cotizar y contactar (épica agregada) | D10: Necesito conocer la agencia, cotizar en línea y dejar mis datos, para recibir un plan sugerido y ser contactada. | E10: 2, 8 | F10: =COUNTIF('Historias de Usuario'!$I$5:$I$60,"E5*") | G10: =SUMIF('Historias de Usuario'!$I$5:$I$60,"E5*",'Historias de Usuario'!$F$5:$F$60)
B11: T | C11: Transversal — historias habilitadoras | D11: Autenticación, entorno, integración continua, pruebas, despliegue y documentación que sirven a todos los roles. | E11: 1 (y calidad del producto) | F11: =COUNTIF('Historias de Usuario'!$I$5:$I$60,"T*") | G11: =SUMIF('Historias de Usuario'!$I$5:$I$60,"T*",'Historias de Usuario'!$F$5:$F$60)
B12: Total | F12: =SUM(F6:F11) | G12: =SUM(G6:G11)
B14: 2. Resumen por sprint
B15: Sprint | C15: Nombre | D15: Hito / entregable (según Carta Gantt) | E15: Semanas | F15: N.º de historias | G15: Puntos
B16: Sprint 0 | C16: Levantamiento y diseño | D16: Hito 1 — Proyecto definido. Los documentos de diseño se gestionan como tareas del sprint. | E16: S1–S4 | F16: =COUNTIF('Historias de Usuario'!$G$5:$G$60,B16) | G16: =SUMIF('Historias de Usuario'!$G$5:$G$60,B16,'Historias de Usuario'!$F$5:$F$60)
B17: Sprint 1 | C17: Base del sistema y sitio corporativo | D17: Autenticación, roles y aislamiento; catálogo; sitio corporativo y CMS; SEO, analítica y captación. | E17: S5–S8 | F17: =COUNTIF('Historias de Usuario'!$G$5:$G$60,B17) | G17: =SUMIF('Historias de Usuario'!$G$5:$G$60,B17,'Historias de Usuario'!$F$5:$F$60)
B18: Sprint 2 | C18: Gestión comercial | D18: Prospectos, cotizador y conversión a cliente. | E18: S9–S11 | F18: =COUNTIF('Historias de Usuario'!$G$5:$G$60,B18) | G18: =SUMIF('Historias de Usuario'!$G$5:$G$60,B18,'Historias de Usuario'!$F$5:$F$60)
B19: Sprint 3 | C19: Portal de clientes | D19: Hito 2 — Sitio corporativo en línea (según Carta Gantt). | E19: S12–S14 | F19: =COUNTIF('Historias de Usuario'!$G$5:$G$60,B19) | G19: =SUMIF('Historias de Usuario'!$G$5:$G$60,B19,'Historias de Usuario'!$F$5:$F$60)
B20: Sprint 4 | C20: Métricas e IA | D20: Dashboards, KPIs y funcionalidades de IA. | E20: S15–S17 | F20: =COUNTIF('Historias de Usuario'!$G$5:$G$60,B20) | G20: =SUMIF('Historias de Usuario'!$G$5:$G$60,B20,'Historias de Usuario'!$F$5:$F$60)
B21: Sprint 5 | C21: Pruebas, despliegue y cierre | D21: Hito 3 — Acta de aceptación e informe final. | E21: S17–S18 | F21: =COUNTIF('Historias de Usuario'!$G$5:$G$60,B21) | G21: =SUMIF('Historias de Usuario'!$G$5:$G$60,B21,'Historias de Usuario'!$F$5:$F$60)
B22: Total | F22: =SUM(F16:F21) | G22: =SUM(G16:G21)
B24: 3. Supuestos y pendientes por validar
B25: N.º | C25: Tema | D25: Detalle
B26: 1 | C26: Prioridad y sprint | D26: La asignación de sprint sigue la Carta Gantt. La prioridad es una propuesta que debe confirmar el Product Owner.
B27: 2 | C27: Épicas | D27: Se usaron las 4 épicas por rol de la presentación del proyecto (diap. 9) y se agregaron E5 (prospecto/visitante) y T (transversal).
B28: 3 | C28: Objetivos específicos | D28: Numerados del 1 al 9 en el orden en que figuran los objetivos específicos del proyecto.
B29: 4 | C29: Estado | D29: Estado según el avance real al 22 oct 2026 (Trello, cierre del Sprint 2): Planificada = por hacer; En Proceso = en desarrollo o en revisión; Hecho = validada contra sus criterios de aceptación. Actualizar al cierre de cada sprint.
B30: 5 | C30: Integración con Meta | D30: PC-MET-02 depende de la aprobación de la app ante Meta (riesgo R-48 de la Planilla de riesgos). El camino garantizado es la carga por archivo (PC-MET-01).
B31: 6 | C31: Sin objetivo directo | D31: PC-IA-03 (copy con voz de marca) no tiene un objetivo específico asociado. Decidir si se vincula al objetivo 5 o se agrega un objetivo.
B32: 7 | C32: Roles | D32: Este backlog usa 4 roles (administradora, colaboradora, cliente aprobador y cliente lector). El Plan de Pruebas usa 3 (administrador, usuario de la agencia y usuario cliente). Unificar el criterio en ambos documentos.
B33: 8 | C33: Sprint 0 | D33: Solo PC-TEC-01 figura como historia. El resto del Sprint 0 son documentos y diseño (alcance, requerimientos, arquitectura, modelo de datos, prototipos), que se gestionan como tareas del Sprint Backlog.
B34: 9 | C34: Proveedor de IA | D34: PC-IA-01 se conectó a Gemini con Google AI Studio como solución de prueba. Más adelante se probará Vertex AI y se decidirá con cuál quedarse. Además, la revisión de la administradora de los diagnósticos con IA es opcional.

Sheet Leyenda
B1: Leyenda del Product Backlog
B2: Cómo leer identificadores, objetivos, esfuerzo, estado y prioridad
B4: 1. Identificadores (ejemplo: PC-AUT-01)
B5: Parte | C5: Significado | D5: Detalle
B6: PC | C6: Plataforma Cosmopolitan | D6: Prefijo fijo de todas las historias del proyecto.
B7: AUT | C7: Módulo o tema de la historia | D7: Código de tres letras (o dos, en IA). Ver la tabla de módulos más abajo.
B8: 01 | C8: Número correlativo dentro del módulo | D8: No indica prioridad ni orden de construcción. La prioridad y el sprint están en sus propias columnas.
B10: 2. Módulos
B11: Código | C11: Módulo | D11: Ejemplo de historia
B12: AUT | C12: Autenticación, roles y aislamiento | D12: PC-AUT-05 · Cliente solo ve su empresa
B13: CAT | C13: Catálogo de planes y servicios | D13: PC-CAT-01 · Catálogo de planes
B14: WEB | C14: Sitio corporativo y CMS | D14: PC-WEB-02 · CMS del sitio
B15: SEO | C15: SEO y analítica | D15: PC-SEO-02 · Analítica con consentimiento
B16: CAP | C16: Captación de prospectos desde el sitio | D16: PC-CAP-01 · Formulario de captación
B17: PRO | C17: Gestión de prospectos | D17: PC-PRO-01 · Prospectos en lista y kanban
B18: COT | C18: Cotizador | D18: PC-COT-01 · Cotizador en línea
B19: CLI | C19: Clientes | D19: PC-CLI-02 · Ficha del cliente
B20: POR | C20: Portal del cliente | D20: PC-POR-01 · Portal del cliente
B21: CAL | C21: Calendario editorial | D21: PC-CAL-01 · Cargar contenido y enviar a revisión
B22: APR | C22: Aprobación de contenido | D22: PC-APR-01 · Aprobar o pedir cambios
... B33: ACE | C33: Aceptación | D33: PC-ACE-01 · Validación y acta de aceptación
B35: 3. Objetivos específicos (las referencias "Obj." de la columna Comentarios)
B36: Obj. | C36: Objetivo específico | D36: Nota
B37: 1 | C37: Autenticación con roles y aislamiento estricto de información entre clientes.
B38: 2 | C38: Registrar prospectos desde el sitio público y gestionar su avance hasta la conversión en cliente.
B39: 3 | C39: Modelar los planes y servicios de la agencia de forma administrable, sin intervención en código.
B40: 4 | C40: Controlar el cumplimiento de la cuota mensual de entregables de cada plan contratado.
B41: 5 | C41: Formalizar el ciclo semanal de producción, envío, aprobación y versionado de contenido.
B42: 6 | C42: Consolidar métricas de redes y campañas en dashboards por cliente.
B43: 7 | C43: Reducir el tiempo de elaboración del reporte mensual mediante generación asistida por IA.
B44: 8 | C44: Reducir el tiempo de elaboración del diagnóstico de cotización mediante generación asistida por IA.
B45: 9 | C45: Habilitar un portal donde cada clienta acceda únicamente a su información.
B47: 4. Cómo leer la columna Comentarios
B48: Elemento | C48: Significado | D48: Ejemplo
B49: E1 a E5, T | C49: Épica a la que pertenece la historia (T = transversal). Ver la hoja "Épicas y resumen". | D49: E1 = Administradora · E2 = Colaboradora · E3 = Cliente aprobador · E4 = Cliente lector · E5 = Prospecto / visitante
B50: Obj. n | C50: Objetivo(s) específico(s) que la historia ayuda a cumplir (sección 3). | D50: Obj. 1 y 9 = autenticación y aislamiento, y portal del cliente
B51: CP-xxx, R-xx, RNF-xx | C51: Referencias a otros documentos del proyecto: CP = caso de prueba del Plan de Pruebas; R = riesgo de la Planilla de riesgos; RNF = requerimiento no funcional de la Especificación de requerimientos. | D51: Se verifica con CP-020 · Riesgo R-32
B52: Texto restante | C52: Explicación breve de la historia y de para qué sirve, con sus dependencias, riesgos (R-xx) y casos de prueba (CP-xxx) relacionados. | D52: Ningún cliente puede ver datos de otro. Se prueba con CP-020 y CP-021.
B54: 5. Dimensión / esfuerzo (puntos de historia)
B55: Puntos | C55: Significado | D55: Cómo usarlo
...

Sheet Instructivo
B1: Pila de Producto (Product Backlog): Instructivo
B2: Elaborado por: pmoinformatica.com
B4: Columna | C4: Instrucciones
B5: Identificador (ID) de la Historia | C5: Código que identifica a la historia de forma unívoca, una vez asignado, no debe ser re-usado en otra historia, ni siquiera si la historia es descartada. El código identifica la historia en otros documentos, como por ejemplo la plantilla de historias de usuario.
B6: Enunciado de la Historia | C6: Nombre de la historia, el cual debe ser el mismo que se utiliza en otros documentos. Se puede utilizar el formato siguiente: Como un [Rol], Necesito [Descripción de la Funcionalidad], con la finalidad de [Razón o Resultado]
B7: Alias | C7: Título de la historia alternativo a la descripción, que servirá para identificar más fácilmente la historia sin tener que repetir todo su enunciado. Se puede utilizar por ejemplo el nombre de la funcionalidad o requerimiento que se pretende desarrollar.
B8: Estado | C8: Identifica los posibles estados de la historia durante su ciclo de vida: - Vacío: La historia fue identifica pero aún no ha sido asignada a una iteración. - Planificada: La historia fue asignada a una iteración y aún no ha comenzado su ejecución. Puede tener este estado incluyendo en la iteración donde está planificado ejecutarla (pero que aún no ha comenzado). - En Proceso: La historia fue seleccionada por el equipo y está en proceso de desarrollo (en ejecución). - Hecho (Donde): La historia fue desarrollada. Es importante clarificar la definición de “Hecho” con el equipo de trabajo. “Hecho” no sólo incluye el desarrollo sino la integración y pruebas integrales del Software. Una historia hecha puede presentarse al dueño de producto para sus pruebas de aceptación. - Descartada: Se determinó que la historia ya no es relevante, su contenido se incluyó en otro grupo de historias o fue cancelada.
B9: Dimensión / Esfuerzo | C9: Medida del esfuerzo (tamaño) que implica desarrollar la historia, existen distintos métodos para medirlo, un ejemplo es los “puntos de historia” una medida de complejidad no necesariamente relacionado con jornadas o días. Otra forma de medirlo es con días o jornadas ideales.
B10: Iteración (Sprint) | C10: Iteración o Sprint al que se asigna la historia. Esta asignación puede cambiar en cada iteración donde se haga la revisión de la pila de producto (ProductBacklogReview), según las prioridades indicadas por el dueño de producto. Por medio de este campo se puede crear un “Plan de Salidas a Productivo” (Release Plan).
B11: Prioridad | C11: Siguiendo el marco de trabajo ágil y Scrum, se le deben asignar prioridades a las historias, según las instrucciones del dueño de producto (ProductOwner). De esta forma pueden ordenarse. Las historias de mayor prioridad deben ser las que agregan más valor al negocio, y deben ser originadas en sus necesidades.
B12: Comentarios | C12: Comentarios o detalles relacionadas que expliquen la historia. Para definiciones de mayor longitud deben usarse documentos externos, por ejemplo la plantilla de historias de usuario.
B13: Criterios de aceptación | C13: Condiciones verificables que deben cumplirse para dar la historia por terminada. La historia se acepta solo si se cumplen todos sus criterios y pasan sus casos de prueba asociados.
B14: Casos de prueba | C14: Casos del Plan de Pruebas que verifican la historia (trazabilidad). Un guion (—) indica que la historia se verifica directamente contra sus criterios de aceptación.
